<?xml version="1.0" ?>
<sdf version="1.8">
  <model name="quadrotor">
    <pose>0 0 1.0 0 0 0</pose>
    <link name="base_link">
      <pose>0 0 0 0 0 0</pose>
      <inertial>
        <pose>0 0 0 0 0 0</pose>
        <mass>1.5</mass>
        <inertia>
          <ixx>0.00925</ixx><ixy>0</ixy><ixz>0</ixz>
          <iyy>0.00925</iyy><iyz>0</iyz>
          <izz>0.01688</izz>
        </inertia>
      </inertial>
      <visual name="body_visual">
        <geometry><cylinder><radius>0.15</radius><length>0.08</length></cylinder></geometry>
        <material><ambient>0.3 0.3 0.3 1</ambient><diffuse>0.3 0.3 0.3 1</diffuse></material>
      </visual>
      <collision name="body_collision">
        <geometry><cylinder><radius>0.15</radius><length>0.08</length></cylinder></geometry>
      </collision>
      <visual name="arm_0_visual">
        <pose>0.125 0.125 0.01 0 0 0.7854</pose>
        <geometry><box><size>0.354 0.04 0.04</size></box></geometry>
        <material><ambient>0.15 0.15 0.15 1</ambient><diffuse>0.15 0.15 0.15 1</diffuse></material>
      </visual>
      <visual name="arm_1_visual">
        <pose>0.125 -0.125 0.01 0 0 -0.7854</pose>
        <geometry><box><size>0.354 0.04 0.04</size></box></geometry>
        <material><ambient>0.15 0.15 0.15 1</ambient><diffuse>0.15 0.15 0.15 1</diffuse></material>
      </visual>
      <visual name="arm_2_visual">
        <pose>-0.125 -0.125 0.01 0 0 0.7854</pose>
        <geometry><box><size>0.354 0.04 0.04</size></box></geometry>
        <material><ambient>0.15 0.15 0.15 1</ambient><diffuse>0.15 0.15 0.15 1</diffuse></material>
      </visual>
      <visual name="arm_3_visual">
        <pose>-0.125 0.125 0.01 0 0 -0.7854</pose>
        <geometry><box><size>0.354 0.04 0.04</size></box></geometry>
        <material><ambient>0.15 0.15 0.15 1</ambient><diffuse>0.15 0.15 0.15 1</diffuse></material>
      </visual>
      <sensor name="imu_sensor" type="imu">
        <always_on>true</always_on>
        <update_rate>100</update_rate>
        <topic>quadrotor/imu</topic>
      </sensor>
    </link>
    <link name="rotor_0">
      <pose relative_to="base_link">0.25 0.25 0.02 0 0 0</pose>
      <inertial>
        <pose>0 0 0 0 0 0</pose>
        <mass>0.05</mass>
        <inertia><ixx>0.0001</ixx><ixy>0</ixy><ixz>0</ixz><iyy>0.0001</iyy><iyz>0</iyz><izz>0.0002</izz></inertia>
      </inertial>
      <visual name="rotor_0_visual">
        <geometry><cylinder><radius>0.1</radius><length>0.005</length></cylinder></geometry>
        <material><ambient>0.7 0.7 0.7 1</ambient><diffuse>0.7 0.7 0.7 1</diffuse></material>
      </visual>
      <collision name="rotor_0_collision">
        <geometry><cylinder><radius>0.1</radius><length>0.005</length></cylinder></geometry>
      </collision>
    </link>
    <joint name="rotor_0_joint" type="revolute">
      <parent>base_link</parent>
      <child>rotor_0</child>
      <!-- Rotor spin axis (motor model drives angular velocity on this joint). -->
      <axis>
        <xyz>0 0 1</xyz>
        <limit>
          <lower>-1000000</lower>
          <upper>1000000</upper>
          <!-- Gazebo warns when velocity control is used but joint axis has no effort limit. -->
          <effort>1000000</effort>
          <velocity>1000000</velocity>
        </limit>
        <dynamics>
          <damping>0.01</damping>
        </dynamics>
      </axis>
    </joint>
    <link name="rotor_1">
      <pose relative_to="base_link">0.25 -0.25 0.02 0 0 0</pose>
      <inertial>
        <pose>0 0 0 0 0 0</pose>
        <mass>0.05</mass>
        <inertia><ixx>0.0001</ixx><ixy>0</ixy><ixz>0</ixz><iyy>0.0001</iyy><iyz>0</iyz><izz>0.0002</izz></inertia>
      </inertial>
      <visual name="rotor_1_visual">
        <geometry><cylinder><radius>0.1</radius><length>0.005</length></cylinder></geometry>
        <material><ambient>0.7 0.7 0.7 1</ambient><diffuse>0.7 0.7 0.7 1</diffuse></material>
      </visual>
      <collision name="rotor_1_collision">
        <geometry><cylinder><radius>0.1</radius><length>0.005</length></cylinder></geometry>
      </collision>
    </link>
    <joint name="rotor_1_joint" type="revolute">
      <parent>base_link</parent>
      <child>rotor_1</child>
      <!-- Rotor spin axis (motor model drives angular velocity on this joint). -->
      <axis>
        <xyz>0 0 1</xyz>
        <limit>
          <lower>-1000000</lower>
          <upper>1000000</upper>
          <!-- Gazebo warns when velocity control is used but joint axis has no effort limit. -->
          <effort>1000000</effort>
          <velocity>1000000</velocity>
        </limit>
        <dynamics>
          <damping>0.01</damping>
        </dynamics>
      </axis>
    </joint>
    <link name="rotor_2">
      <pose relative_to="base_link">-0.25 -0.25 0.02 0 0 0</pose>
      <inertial>
        <pose>0 0 0 0 0 0</pose>
        <mass>0.05</mass>
        <inertia><ixx>0.0001</ixx><ixy>0</ixy><ixz>0</ixz><iyy>0.0001</iyy><iyz>0</iyz><izz>0.0002</izz></inertia>
      </inertial>
      <visual name="rotor_2_visual">
        <geometry><cylinder><radius>0.1</radius><length>0.005</length></cylinder></geometry>
        <material><ambient>0.7 0.7 0.7 1</ambient><diffuse>0.7 0.7 0.7 1</diffuse></material>
      </visual>
      <collision name="rotor_2_collision">
        <geometry><cylinder><radius>0.1</radius><length>0.005</length></cylinder></geometry>
      </collision>
    </link>
    <joint name="rotor_2_joint" type="revolute">
      <parent>base_link</parent>
      <child>rotor_2</child>
      <!-- Rotor spin axis (motor model drives angular velocity on this joint). -->
      <axis>
        <xyz>0 0 1</xyz>
        <limit>
          <lower>-1000000</lower>
          <upper>1000000</upper>
          <!-- Gazebo warns when velocity control is used but joint axis has no effort limit. -->
          <effort>1000000</effort>
          <velocity>1000000</velocity>
        </limit>
        <dynamics>
          <damping>0.01</damping>
        </dynamics>
      </axis>
    </joint>
    <link name="rotor_3">
      <pose relative_to="base_link">-0.25 0.25 0.02 0 0 0</pose>
      <inertial>
        <pose>0 0 0 0 0 0</pose>
        <mass>0.05</mass>
        <inertia><ixx>0.0001</ixx><ixy>0</ixy><ixz>0</ixz><iyy>0.0001</iyy><iyz>0</iyz><izz>0.0002</izz></inertia>
      </inertial>
      <visual name="rotor_3_visual">
        <geometry><cylinder><radius>0.1</radius><length>0.005</length></cylinder></geometry>
        <material><ambient>0.7 0.7 0.7 1</ambient><diffuse>0.7 0.7 0.7 1</diffuse></material>
      </visual>
      <collision name="rotor_3_collision">
        <geometry><cylinder><radius>0.1</radius><length>0.005</length></cylinder></geometry>
      </collision>
    </link>
    <joint name="rotor_3_joint" type="revolute">
      <parent>base_link</parent>
      <child>rotor_3</child>
      <!-- Rotor spin axis (motor model drives angular velocity on this joint). -->
      <axis>
        <xyz>0 0 1</xyz>
        <limit>
          <lower>-1000000</lower>
          <upper>1000000</upper>
          <!-- Gazebo warns when velocity control is used but joint axis has no effort limit. -->
          <effort>1000000</effort>
          <velocity>1000000</velocity>
        </limit>
        <dynamics>
          <damping>0.01</damping>
        </dynamics>
      </axis>
    </joint>
    <plugin filename="gz-sim-multicopter-motor-model-system"
            name="gz::sim::systems::MulticopterMotorModel">
      <robotNamespace>quadrotor</robotNamespace>
      <jointName>rotor_0_joint</jointName>
      <linkName>rotor_0</linkName>
      <turningDirection>ccw</turningDirection>
      <timeConstantUp>0.0125</timeConstantUp>
      <timeConstantDown>0.025</timeConstantDown>
      <maxRotVelocity>800.0</maxRotVelocity>
      <motorConstant>8.54858e-06</motorConstant>
      <momentConstant>0.016</momentConstant>
      <commandSubTopic>command/motor_speed</commandSubTopic>
      <actuator_number>0</actuator_number>
      <motorType>velocity</motorType>
      <rotorDragCoefficient>8.06428e-05</rotorDragCoefficient>
      <rollingMomentCoefficient>1e-06</rollingMomentCoefficient>
      <motorSpeedPubTopic>motor_speed/0</motorSpeedPubTopic>
      <rotorVelocitySlowdownSim>10</rotorVelocitySlowdownSim>
    </plugin>
    <plugin filename="gz-sim-multicopter-motor-model-system"
            name="gz::sim::systems::MulticopterMotorModel">
      <robotNamespace>quadrotor</robotNamespace>
      <jointName>rotor_1_joint</jointName>
      <linkName>rotor_1</linkName>
      <turningDirection>cw</turningDirection>
      <timeConstantUp>0.0125</timeConstantUp>
      <timeConstantDown>0.025</timeConstantDown>
      <maxRotVelocity>800.0</maxRotVelocity>
      <motorConstant>8.54858e-06</motorConstant>
      <momentConstant>0.016</momentConstant>
      <commandSubTopic>command/motor_speed</commandSubTopic>
      <actuator_number>1</actuator_number>
      <motorType>velocity</motorType>
      <rotorDragCoefficient>8.06428e-05</rotorDragCoefficient>
      <rollingMomentCoefficient>1e-06</rollingMomentCoefficient>
      <motorSpeedPubTopic>motor_speed/1</motorSpeedPubTopic>
      <rotorVelocitySlowdownSim>10</rotorVelocitySlowdownSim>
    </plugin>
    <plugin filename="gz-sim-multicopter-motor-model-system"
            name="gz::sim::systems::MulticopterMotorModel">
      <robotNamespace>quadrotor</robotNamespace>
      <jointName>rotor_2_joint</jointName>
      <linkName>rotor_2</linkName>
      <turningDirection>ccw</turningDirection>
      <timeConstantUp>0.0125</timeConstantUp>
      <timeConstantDown>0.025</timeConstantDown>
      <maxRotVelocity>800.0</maxRotVelocity>
      <motorConstant>8.54858e-06</motorConstant>
      <momentConstant>0.016</momentConstant>
      <commandSubTopic>command/motor_speed</commandSubTopic>
      <actuator_number>2</actuator_number>
      <motorType>velocity</motorType>
      <rotorDragCoefficient>8.06428e-05</rotorDragCoefficient>
      <rollingMomentCoefficient>1e-06</rollingMomentCoefficient>
      <motorSpeedPubTopic>motor_speed/2</motorSpeedPubTopic>
      <rotorVelocitySlowdownSim>10</rotorVelocitySlowdownSim>
    </plugin>
    <plugin filename="gz-sim-multicopter-motor-model-system"
            name="gz::sim::systems::MulticopterMotorModel">
      <robotNamespace>quadrotor</robotNamespace>
      <jointName>rotor_3_joint</jointName>
      <linkName>rotor_3</linkName>
      <turningDirection>cw</turningDirection>
      <timeConstantUp>0.0125</timeConstantUp>
      <timeConstantDown>0.025</timeConstantDown>
      <maxRotVelocity>800.0</maxRotVelocity>
      <motorConstant>8.54858e-06</motorConstant>
      <momentConstant>0.016</momentConstant>
      <commandSubTopic>command/motor_speed</commandSubTopic>
      <actuator_number>3</actuator_number>
      <motorType>velocity</motorType>
      <rotorDragCoefficient>8.06428e-05</rotorDragCoefficient>
      <rollingMomentCoefficient>1e-06</rollingMomentCoefficient>
      <motorSpeedPubTopic>motor_speed/3</motorSpeedPubTopic>
      <rotorVelocitySlowdownSim>10</rotorVelocitySlowdownSim>
    </plugin>
    <plugin filename="gz-sim-multicopter-control-system"
            name="gz::sim::systems::MulticopterVelocityControl">
      <robotNamespace>quadrotor</robotNamespace>
      <commandSubTopic>cmd_vel</commandSubTopic>
      <enableSubTopic>enable</enableSubTopic>
      <comLinkName>base_link</comLinkName>
      <velocityGain>2.7 2.7 2.7</velocityGain>
      <attitudeGain>2.0 2.0 2.0</attitudeGain>
      <angularRateGain>0.15 0.15 0.15</angularRateGain>
      <maximumLinearAcceleration>2 2 2</maximumLinearAcceleration>
      <robotBaseFrameId>base_link</robotBaseFrameId>
      <odometrySubTopic>odom</odometrySubTopic>
      <odometryPubTopic>odom</odometryPubTopic>
      <rotorConfiguration>
        <rotor>
          <jointName>rotor_0_joint</jointName>
          <forceConstant>8.54858e-06</forceConstant>
          <momentConstant>0.016</momentConstant>
          <direction>1</direction>
        </rotor>
        <rotor>
          <jointName>rotor_1_joint</jointName>
          <forceConstant>8.54858e-06</forceConstant>
          <momentConstant>0.016</momentConstant>
          <direction>-1</direction>
        </rotor>
        <rotor>
          <jointName>rotor_2_joint</jointName>
          <forceConstant>8.54858e-06</forceConstant>
          <momentConstant>0.016</momentConstant>
          <direction>1</direction>
        </rotor>
        <rotor>
          <jointName>rotor_3_joint</jointName>
          <forceConstant>8.54858e-06</forceConstant>
          <momentConstant>0.016</momentConstant>
          <direction>-1</direction>
        </rotor>
      </rotorConfiguration>
    </plugin>
    <plugin filename="gz-sim-imu-system"
            name="gz::sim::systems::Imu"/>
    <plugin filename="gz-sim-odometry-publisher-system"
            name="gz::sim::systems::OdometryPublisher">
      <odom_topic>/quadrotor/odom</odom_topic>
      <odom_publish_frequency>50</odom_publish_frequency>
      <dimensions>3</dimensions>
      <robot_base_frame>base_link</robot_base_frame>
    </plugin>
  </model>
</sdf>
